Workbook

Sheet ABOUT

Sheet areas_usgs
A1: num | B1: gage | C1: usgs_area | D1: ESRI watersheds | E1: delineator.py watersheds | F1: pd_esri | G1: pd_mine | H1: cac_mine | I1: cac_esri
A2: 1 | B2: 01015800 | C2: 2318.047 | D2: 2318.201 | E2: 2311.9396 | F2: {=[1]!Perc_Diff(D2,C2)} -> 6.6451711e-05 | G2: {=[1]!Perc_Diff(E2,C2)} -> -0.002641664 | H2: 0.9937787 | I2: 0.99709483 | K2: n | L2: =COUNT(areas_usgs!$H$2:$H$101) -> 100 | M2: =COUNT(areas_usgs!$I$2:$I$101) -> 100
A3: 2 | B3: 01092000 | C3: 7987.3833 | D3: 0.023 | E3: 7921.9231 | F3: {=[1]!Perc_Diff(D3,C3)} -> -347276.53 | G3: {=[1]!Perc_Diff(E3,C3)} -> -0.0082631661 | H3: 0.91799721 | I3: 0.93668104 | K3: Median | L3: =MEDIAN(areas_usgs!$H$2:$H$101) -> 0.97984335 | M3: =MEDIAN(areas_usgs!$I$2:$I$101) -> 0.99025634
A4: 3 | B4: 01094000 | C4: 441.13851 | D4: 440.336 | E4: 445.93117 | F4: {=[1]!Perc_Diff(D4,C4)} -> -0.0018225046 | G4: {=[1]!Perc_Diff(E4,C4)} -> 0.010747516 | H4: 0.97959382 | I4: 0.98831503 | K4: Average | L4: =AVERAGE(areas_usgs!$H$2:$H$101) -> 0.9275877 | M4: =AVERAGE(areas_usgs!$I$2:$I$101) -> 0.83495676
A5: 4 | B5: 01170500 | C5: 20373.543 | D5: 20353.547 | E5: 20438.921 | F5: {=[1]!Perc_Diff(D5,C5)} -> -0.00098244655 | G5: {=[1]!Perc_Diff(E5,C5)} -> 0.0031986984 | H5: 0.99787229 | I5: 2.5028408e-05 | K5: St. Dev. | L5: =STDEV(areas_usgs!$H$2:$H$101) -> 0.15378537 | M5: =STDEV(areas_usgs!$I$2:$I$101) -> 0.34539253
A6: 5 | B6: 01209901 | C6: 94.200207 | D6: 89.896 | E6: 87.759228 | F6: {=[1]!Perc_Diff(D6,C6)} -> -0.047879855 | G6: {=[1]!Perc_Diff(E6,C6)} -> -0.073393751 | H6: 0.84294251 | I6: 0.99621303 | K6: -------- | L6: -------- | M6: --------
A7: 6 | B7: 01318500 | C7: 4304.6376 | D7: 4304.451 | E7: 4288.1049 | F7: {=[1]!Perc_Diff(D7,C7)} -> -4.3346265e-05 | G7: {=[1]!Perc_Diff(E7,C7)} -> -0.0038554864 | H7: 0.97166049 | I7: 9.5006502e-06 | K7: Min. | L7: =MIN(areas_usgs!$H$2:$H$101) -> 0.0072751109 | M7: =MIN(areas_usgs!$I$2:$I$101) -> 1.4627264e-08 | T7: 10 | U7: 10
A8: 7 | B8: 01403060 | C8: 2022.5242 | D8: 2022.132 | E8: 1953.3166 | F8: {=[1]!Perc_Diff(D8,C8)} -> -0.0001939587 | G8: {=[1]!Perc_Diff(E8,C8)} -> -0.03543083 | H8: 0.97543909 | I8: 1.4627264e-08 | K8: 10%-ile | L8: =PERCENTILE(areas_usgs!$H$2:$H$101, 0.1) -> 0.85159492 | M8: =PERCENTILE(areas_usgs!$I$2:$I$101, 0.1) -> 9.4076326e-05 | T8: 1000000 | U8: 1000000
A9: 8 | B9: 01431500 | C9: 746.49493 | D9: 745.966 | E9: 753.82353 | F9: {=[1]!Perc_Diff(D9,C9)} -> -0.00070905484 | G9: {=[1]!Perc_Diff(E9,C9)} -> 0.0097219095 | H9: 0.98687253 | I9: 0.97229542 | K9: 25%-ile | L9: =PERCENTILE(areas_usgs!$H$2:$H$101, 0.25) -> 0.93425516 | M9: =PERCENTILE(areas_usgs!$I$2:$I$101, 0.25) -> 0.95129544
A10: 9 | B10: 01464907 | C10: 71.124095 | D10: 70.189 | E10: 70.682286 | F10: {=[1]!Perc_Diff(D10,C10)} -> -0.013322535 | G10: {=[1]!Perc_Diff(E10,C10)} -> -0.0062506413 | H10: 0.98685757 | I10: 0.98874248 | K10: 50%-ile | L10: =PERCENTILE(areas_usgs!$H$2:$H$101, 0.5) -> 0.97984335 | M10: =PERCENTILE(areas_usgs!$I$2:$I$101, 0.5) -> 0.99025634
A11: 10 | B11: 01480870 | C11: 232.44566 | D11: 234.129 | E11: 233.3364 | F11: {=[1]!Perc_Diff(D11,C11)} -> 0.0071897866 | G11: {=[1]!Perc_Diff(E11,C11)} -> 0.0038174143 | H11: 0.93456457 | I11: 0.95484692 | K11: 75%-ile | L11: =PERCENTILE(areas_usgs!$H$2:$H$101, 0.75) -> 0.99049837 | M11: =PERCENTILE(areas_usgs!$I$2:$I$101, 0.75) -> 0.99544129
A12: 11 | B12: 01488500 | C12: 127.36828 | D12: 121.817 | E12: 99.651175 | F12: {=[1]!Perc_Diff(D12,C12)} -> -0.045570666 | G12: {=[1]!Perc_Diff(E12,C12)} -> -0.2781413 | H12: 0.78787219 | I12: 0.96304167 | K12: 90%-ile | L12: =PERCENTILE(areas_usgs!$H$2:$H$101, 0.9) -> 0.99389255 | M12: =PERCENTILE(areas_usgs!$I$2:$I$101, 0.9) -> 0.99725393
A13: 12 | B13: 01520500 | C13: 1988.1374 | D13: 1987.549 | E13: 2007.331 | F13: {=[1]!Perc_Diff(D13,C13)} -> -0.00029603804 | G13: {=[1]!Perc_Diff(E13,C13)} -> 0.0095617497 | H13: 0.88721408 | I13: 0.98057956 | K13: Max. | L13: =MAX(areas_usgs!$H$2:$H$101) -> 0.99868546 | M13: =MAX(areas_usgs!$I$2:$I$101) -> 0.99893496
A14: 13 | B14: 01555500 | C14: 426.62628 | D14: 420.69 | E14: 421.52686 | F14: {=[1]!Perc_Diff(D14,C14)} -> -0.014110829 | G14: {=[1]!Perc_Diff(E14,C14)} -> -0.012097506 | H14: 0.9938389 | I14: 0.9976338 | K14: ----- | L14: ----- | M14: -----
A15: 14 | B15: 01567000 | C15: 8681.3829 | D15: 8680.681 | E15: 8682.95 | F15: {=[1]!Perc_Diff(D15,C15)} -> -8.085651e-05 | G15: {=[1]!Perc_Diff(E15,C15)} -> 0.00018048644 | H15: 0.98747899 | I15: 0.99532531 | K15: Coeff. of Variation | L15: =STDEV(areas_usgs!$H$2:$H$101)/AVERAGE(areas_usgs!$H$2:$H$101) -> 0.16579065 | M15: =STDEV(areas_usgs!$I$2:$I$101)/AVERAGE(areas_usgs!$I$2:$I$101) -> 0.41366517
A16: 15 | B16: 02070500 | C16: 673.34772 | D16: 672.441 | E16: 672.70573 | F16: {=[1]!Perc_Diff(D16,C16)} -> -0.0013484016 | G16: {=[1]!Perc_Diff(E16,C16)} -> -0.00095433392 | H16: 0.89126257 | I16: 0.78108248 | K16: Coeff. of Skew | L16: =SKEW(areas_usgs!$H$2:$H$101) -> -4.3764902 | M16: =SKEW(areas_usgs!$I$2:$I$101) -> -1.9786196
A17: 16 | B17: 02110500 | C17: 2913.1803 | D17: 2913.117 | E17: 2908.0215 | F17: {=[1]!Perc_Diff(D17,C17)} -> -2.1745497e-05 | G17: {=[1]!Perc_Diff(E17,C17)} -> -0.0017739968 | H17: 0.50976896 | I17: 0.99028359
A18: 17 | B18: 02131000 | C18: 22833.073 | D18: 22830.317 | E18: 22836.399 | F18: {=[1]!Perc_Diff(D18,C18)} -> -0.00012071273 | G18: {=[1]!Perc_Diff(E18,C18)} -> 0.00014563123 | H18: 0.9915317 | I18: 0.99344864
A19: 18 | B19: 02225500 | C19: 2931.5219 | D19: 2931.56 | E19: 2920.2545 | F19: {=[1]!Perc_Diff(D19,C19)} -> 1.3006425e-05 | G19: {=[1]!Perc_Diff(E19,C19)} -> -0.0038583438 | H19: 0.98344277 | I19: 0.9931797
A20: 19 | B20: 02226500 | C20: 3238.72 | D20: 3239.862 | E20: 3068.0905 | F20: {=[1]!Perc_Diff(D20,C20)} -> 0.00035249418 | G20: {=[1]!Perc_Diff(E20,C20)} -> -0.055614233 | H20: 0.97044567 | I20: 0.98999767
A21: 20 | B21: 02299950 | C21: 182.19197 | D21: 179.585 | E21: 162.09523 | F21: {=[1]!Perc_Diff(D21,C21)} -> -0.014516646 | G21: {=[1]!Perc_Diff(E21,C21)} -> -0.12398105 | H21: 0.99586485 | I21: 0.9967337
A22: 21 | B22: 02365200 | C22: 8245.2114 | D22: 8246.978 | E22: 8278.7865 | F22: {=[1]!Perc_Diff(D22,C22)} -> 0.00021421264 | G22: {=[1]!Perc_Diff(E22,C22)} -> 0.0040555631 | H22: 0.97009281 | I22: 0.99893496
A23: 22 | B23: 02374500 | C23: 456.6949 | D23: 456.237 | E23: 434.60147 | F23: {=[1]!Perc_Diff(D23,C23)} -> -0.0010036418 | G23: {=[1]!Perc_Diff(E23,C23)} -> -0.050836071 | H23: 0.96989005 | I23: 0.97717524
A24: 23 | B24: 03050000 | C24: 486.46749 | D24: 486.131 | E24: 488.67569 | F24: {=[1]!Perc_Diff(D24,C24)} -> -0.00069217549 | G24: {=[1]!Perc_Diff(E24,C24)} -> 0.0045187571 | H24: 0.99150684 | I24: 0.9906987
A25: 24 | B25: 03072655 | C25: 11548.483 | D25: 4.047 | E25: 11543.931 | F25: {=[1]!Perc_Diff(D25,C25)} -> -2852.591 | G25: {=[1]!Perc_Diff(E25,C25)} -> -0.00039429497 | H25: 0.97895572 | I25: 0.99578922
A26: 25 | B26: 03086000 | C26: 50495.009 | D26: 0.064 | E26: 50446.466 | F26: {=[1]!Perc_Diff(D26,C26)} -> -788983.51 | G26: {=[1]!Perc_Diff(E26,C26)} -> -0.00096226532 | H26: 0.95537452 | I26: 0.99022909
A27: 26 | B27: 03102500 | C27: 369.77526 | D27: 366.044 | E27: 238.9322 | F27: {=[1]!Perc_Diff(D27,C27)} -> -0.010193473 | G27: {=[1]!Perc_Diff(E27,C27)} -> -0.54761587 | H27: 0.89206943 | I27: 0.99482568
A28: 27 | B28: 03155000 | C28: 3926.5798 | D28: 3925.423 | E28: 3925.5406 | F28: {=[1]!Perc_Diff(D28,C28)} -> -0.00029468969 | G28: {=[1]!Perc_Diff(E28,C28)} -> -0.00026471174 | H28: 0.99324549 | I28: 0.99666235
... A55: 54 | B55: 06178000 | C55: 927.67845 | D55: 926.539 | E55: 1069.103 | F55: {=[1]!Perc_Diff(D55,C55)} -> -0.0012297968 | G55: {=[1]!Perc_Diff(E55,C55)} -> 0.13228339 | H55: 0.56848482 | I55: 0.98465859
A56: the | B56: 06278300 | C56: 59.192571 | D56: 58.922 | E56: 58.76019 | F56: {=[1]!Perc_Diff(D56,C56)} -> -0.0045920194 | G56: {=[1]!Perc_Diff(E56,C56)} -> -0.0073583944 | H56: 0.90433052 | I56: 0.99323658
A57: 56 | B57: 06336000 | C57: 16073.74 | D57: 0.402 | E57: 16045.361 | F57: {=[1]!Perc_Diff(D57,C57)} -> -39983.428 | G57: {=[1]!Perc_Diff(E57,C57)} -> -0.00176868 | H57: 0.97016513 | I57: 0.98489912
A58: 57 | B58: 06386500 | C58: 13787.873 | D58: 13786.35 | E58: 13787.435 | F58: {=[1]!Perc_Diff(D58,C58)} -> -0.00011045447 | G58: {=[1]!Perc_Diff(E58,C58)} -> -3.1719048e-05 | H58: 0.97198015 | I58: 0.00011689659
A59: 58 | B59: 06478000 | C59: 43599.051 | D59: 45476.995 | E59: 50380.627 | F59: {=[1]!Perc_Diff(D59,C59)} -> 0.041294369 | G59: {=[1]!Perc_Diff(E59,C59)} -> 0.13460682 | H59: 0.98826895 | I59: 0.96892867
A60: 59 | B60: 06481000 | C60: 7599.4858 | D60: 8709.394 | E60: 9678.6359 | F60: {=[1]!Perc_Diff(D60,C60)} -> 0.12743805 | G60: {=[1]!Perc_Diff(E60,C60)} -> 0.21481851 | H60: 0.97325842 | I60: 5.2868335e-08
A61: 60 | B61: 06600500 | C61: 2297.91 | D61: 2293.466 | E61: 2293.2098 | F61: {=[1]!Perc_Diff(D61,C61)} -> -0.0019376596 | G61: {=[1]!Perc_Diff(E61,C61)} -> -0.0020496125 | H61: 0.96401701 | I61: 0.99425643
A62: 61 | B62: 06620000 | C62: 3686.1672 | D62: 3702.089 | E62: 3702.2866 | F62: {=[1]!Perc_Diff(D62,C62)} -> 0.0043007692 | G62: {=[1]!Perc_Diff(E62,C62)} -> 0.0043539094 | H62: 0.85267815 | I62: 0.93334473
A63: 62 | B63: 06715000 | C63: 225.23338 | D63: 220.147 | E63: 220.33914 | F63: {=[1]!Perc_Diff(D63,C63)} -> -0.023104458 | G63: {=[1]!Perc_Diff(E63,C63)} -> -0.02221231 | H63: 0.99868546 | I63: 0.00034730066
A64: 63 | B64: 06719505 | C64: 1027.1575 | D64: 1022.266 | E64: 1021.2558 | F64: {=[1]!Perc_Diff(D64,C64)} -> -0.0047849094 | G64: {=[1]!Perc_Diff(E64,C64)} -> -0.0057787915 | H64: 0.9618002 | I64: 0.99723067
A65: 64 | B65: 06856600 | C65: 58160.603 | D65: 0.388 | E65: 63596.006 | F65: {=[1]!Perc_Diff(D65,C65)} -> -149897.46 | G65: {=[1]!Perc_Diff(E65,C65)} -> 0.085467675 | H65: 0.88261303 | I65: 0.99588464
A66: 65 | B66: 06870300 | C66: 306.13704 | D66: 302.792 | E66: 335.87608 | F66: {=[1]!Perc_Diff(D66,C66)} -> -0.011047317 | G66: {=[1]!Perc_Diff(E66,C66)} -> 0.088541692 | H66: 0.99390922 | I66: 0.99588744
...
